<?xml version="1.0" ?>
<!-- =================================================================================== -->
<!-- |    This document was autogenerated by xacro from new_korus_jaco_arm.urdf.xacro  | -->
<!-- |    EDITING THIS FILE BY HAND IS NOT RECOMMENDED                                 | -->
<!-- =================================================================================== -->
<robot name="korus_jaco" xmlns:controller="http://playerstage.sourceforge.net/gazebo/xmlschema/#controller" xmlns:interface="http://playerstage.sourceforge.net/gazebo/xmlschema/#interface" xmlns:sensor="http://playerstage.sourceforge.net/gazebo/xmlschema/#sensor" xmlns:xacro="http://www.ros.org/wiki/xacro">
  <!--   <include filename="$(find korus_meta)/resources/urdf/jaco_arm.xacro"/> -->
  <material name="JacoGrey">
    <color rgba="0.2 0.2 0.9 1.0"/>
  </material>
  <!-- ************************ omni drive simulation ************************* -->
  <link name="world">
  </link>
  <joint name="omni_drive_x" type="prismatic">
    <parent link="world"/>
    <child link="omni_drive_x_link"/>
    <origin rpy="0 0 0" xyz="-1.0 0 0"/>
    <axis xyz="1 0 0"/>
    <limit effort="10" lower="0.0" upper="2.0" velocity="1.0"/>
  </joint>
  <link name="omni_drive_x_link">
  </link>
  <joint name="omni_drive_y" type="prismatic">
    <parent link="omni_drive_x_link"/>
    <child link="base_footprint"/>
    <origin rpy="0 0 0" xyz="0.0 0 0"/>
    <axis xyz="0 1 0"/>
    <limit effort="10" lower="-1.0" upper="1.0" velocity="1.0"/>
  </joint>
  <!-- ************************ Robot model ************************* -->
  <link name="base_footprint"/>
  <joint name="base_joint" type="fixed">
    <parent link="base_footprint"/>
    <child link="base_link"/>
    <origin rpy="0 0 0" xyz="0.0 0.0 0.075"/>
  </joint>
  <link name="base_link">
    <visual>
      <origin rpy="0 0 0" xyz="0.0 0 0.0875"/>
      <geometry>
        <cylinder length="0.275" radius="0.250"/>
      </geometry>
      <material name="white">
        <color rgba="1 1 1 1"/>
      </material>
    </visual>
    <collision>
      <origin rpy="0 0 0" xyz="0.0 0 0.0875"/>
      <geometry>
        <cylinder length="0.275" radius="0.250"/>
      </geometry>
      <material name="white">
        <color rgba="1 1 1 1"/>
      </material>
    </collision>
  </link>
  <link name="wheel_left">
    <visual>
      <geometry>
        <cylinder length="0.03" radius="0.075"/>
      </geometry>
      <origin rpy="0 1.57079632679 0" xyz="0 0 0"/>
      <material name="black">
        <color rgba="0.1 0.1 0.1 1"/>
      </material>
    </visual>
  </link>
  <joint name="wheel_left" type="continuous">
    <parent link="base_link"/>
    <child link="wheel_left"/>
    <origin rpy="0 0 1.57079632679" xyz="0.0 0.15 0.0"/>
  </joint>
  <link name="wheel_right">
    <visual>
      <geometry>
        <cylinder length="0.03" radius="0.075"/>
      </geometry>
      <origin rpy="0 1.57079632679 0" xyz="0 0 0"/>
      <material name="black">
        <color rgba="0.1 0.1 0.1 1"/>
      </material>
    </visual>
  </link>
  <joint name="wheel_right" type="continuous">
    <parent link="base_link"/>
    <child link="wheel_right"/>
    <origin rpy="0 0 1.57079632679" xyz="0.0 -0.15 0.0"/>
  </joint>
  <link name="caster_front_left">
    <visual>
      <geometry>
        <cylinder length="0.02" radius="0.04"/>
      </geometry>
      <origin rpy="0 1.57079632679 0" xyz="0 0 0"/>
      <material name="black">
        <color rgba="0.1 0.1 0.1 1"/>
      </material>
    </visual>
  </link>
  <joint name="caster_front_left" type="fixed">
    <parent link="base_link"/>
    <child link="caster_front_left"/>
    <origin rpy="0 0 1.57079632679" xyz="0.18 0.1 -0.035"/>
  </joint>
  <link name="caster_front_right">
    <visual>
      <geometry>
        <cylinder length="0.02" radius="0.04"/>
      </geometry>
      <origin rpy="0 1.57079632679 0" xyz="0 0 0"/>
      <material name="black">
        <color rgba="0.1 0.1 0.1 1"/>
      </material>
    </visual>
  </link>
  <joint name="caster_front_right" type="fixed">
    <parent link="base_link"/>
    <child link="caster_front_right"/>
    <origin rpy="0 0 1.57079632679" xyz="0.18 -0.1 -0.035"/>
  </joint>
  <link name="caster_back_left">
    <visual>
      <geometry>
        <cylinder length="0.02" radius="0.04"/>
      </geometry>
      <origin rpy="0 1.57079632679 0" xyz="0 0 0"/>
      <material name="black">
        <color rgba="0.1 0.1 0.1 1"/>
      </material>
    </visual>
  </link>
  <joint name="caster_back_left" type="fixed">
    <parent link="base_link"/>
    <child link="caster_back_left"/>
    <origin rpy="0 0 1.57079632679" xyz="-0.18 0.1 -0.035"/>
  </joint>
  <link name="caster_back_right">
    <visual>
      <geometry>
        <cylinder length="0.02" radius="0.04"/>
      </geometry>
      <origin rpy="0 1.57079632679 0" xyz="0 0 0"/>
      <material name="black">
        <color rgba="0.1 0.1 0.1 1"/>
      </material>
    </visual>
  </link>
  <joint name="caster_back_right" type="fixed">
    <parent link="base_link"/>
    <child link="caster_back_right"/>
    <origin rpy="0 0 1.57079632679" xyz="-0.18 -0.1 -0.035"/>
  </joint>
  <joint name="body" type="revolute">
    <parent link="base_link"/>
    <child link="body_link"/>
    <origin rpy="0 0 0" xyz="0.0 0.0 0.250"/>
    <axis xyz="0 0 1"/>
    <limit effort="10" lower="-3.14159265359" upper="3.14159265359" velocity="0.013"/>
  </joint>
  <link name="body_link">
    <visual>
      <origin rpy="0 0 0" xyz="0.0 0.0 0.0"/>
      <geometry>
        <cylinder length="0.05" radius="0.25"/>
      </geometry>
      <material name="white">
        <color rgba="1 1 1 1"/>
      </material>
    </visual>
    <collision>
      <origin rpy="0 0 0" xyz="0.0 0.0 0.0"/>
      <geometry>
        <cylinder length="0.05" radius="0.25"/>
      </geometry>
      <material name="white">
        <color rgba="1 1 1 1"/>
      </material>
    </collision>
  </link>
  <joint name="tray_joint" type="revolute">
    <parent link="base_link"/>
    <child link="tray_link"/>
    <origin rpy="0 0 0" xyz="0.0 0.0 0.250"/>
    <axis xyz="0 0 1"/>
    <limit effort="10" lower="-3.14159265359" upper="3.14159265359" velocity="0.013"/>
  </joint>
  <link name="tray_link">
    <visual>
      <geometry>
        <box size="0.30 0.20 0.02"/>
      </geometry>
      <origin rpy="0 0.0 0" xyz="0.0 0.15 0.05"/>
      <material name="black">
        <color rgba="0.1 0.1 0.1 1"/>
      </material>
    </visual>
    <collision>
      <geometry>
        <box size="0.30 0.20 0.02"/>
      </geometry>
      <origin rpy="0 0.0 0" xyz="0.0 0.15 0.05"/>
      <material name="black">
        <color rgba="0.1 0.1 0.1 1"/>
      </material>
    </collision>
  </link>
  <joint name="torso_joint" type="fixed">
    <parent link="body_link"/>
    <child link="torso_link"/>
    <origin rpy="0 0 0" xyz="-0.175 0.0 0.025"/>
  </joint>
  <link name="torso_link">
    <visual>
      <geometry>
        <cylinder length="0.60" radius="0.075"/>
      </geometry>
      <origin rpy="0 0 0" xyz="0 0 0.30"/>
      <material name="white">
        <color rgba="1 1 1 1"/>
      </material>
    </visual>
    <collision>
      <geometry>
        <cylinder length="0.60" radius="0.075"/>
      </geometry>
      <origin rpy="0 0 0" xyz="0 0 0.30"/>
    </collision>
  </link>
  <joint name="torso_lift_offset" type="fixed">
    <parent link="torso_link"/>
    <child link="torso_lift_offset_link"/>
    <origin rpy="0 0 0" xyz="0 0 0.25"/>
    <axis xyz="0 0 1"/>
  </joint>
  <link name="torso_lift_offset_link"/>
  <joint name="torso_lift" type="prismatic">
    <parent link="torso_lift_offset_link"/>
    <child link="torso_lift_link"/>
    <origin rpy="0 0 3.14159265359" xyz="0 0 0"/>
    <axis xyz="0 0 1"/>
    <limit effort="10" lower="-0.10" upper="0.22" velocity="0.5"/>
  </joint>
  <link name="torso_lift_link">
    <!--     <visual> -->
    <!--       <geometry> -->
    <!--         <box size="0.10 0.25 0.13"/> -->
    <!--       </geometry> -->
    <!--       <origin xyz="-0.05 0.0 0.0" rpy="0 0 0"/> -->
    <!--       <xacro:insert_block name="material_grey_blue" /> -->
    <!--     </visual> -->
  </link>
  <joint name="head_joint" type="fixed">
    <parent link="torso_lift_link"/>
    <child link="head_link"/>
    <origin rpy="0 0 3.14159265359" xyz="0.0 0.0 0.125"/>
  </joint>
  <link name="head_link">
    <visual>
      <geometry>
        <cylinder length="0.40" radius="0.03"/>
      </geometry>
      <origin rpy="0 0 0" xyz="0.0 0.0 0.2"/>
      <material name="white">
        <color rgba="1 1 1 1"/>
      </material>
    </visual>
  </link>
  <joint name="tablet_pan_joint" type="revolute">
    <parent link="head_link"/>
    <child link="tablet_pan_link"/>
    <origin rpy="0 0 0" xyz="0.0 0.0 0.40"/>
    <axis xyz="0 0 1"/>
    <limit effort="10" lower="-1.57079632679" upper="1.57079632679" velocity="0.013"/>
  </joint>
  <link name="tablet_pan_link">
    <visual>
      <geometry>
        <box size="0.03 0.26 0.03"/>
      </geometry>
      <origin rpy="0.0 0.0 0.0" xyz="0.0 0.0 0.015"/>
      <material name="white">
        <color rgba="1 1 1 1"/>
      </material>
    </visual>
  </link>
  <joint name="tablet_tilt_mount_left_joint" type="fixed">
    <parent link="tablet_pan_link"/>
    <child link="tablet_tilt_mount_left_link"/>
    <origin rpy="0 0 0" xyz="0 0.115 0"/>
  </joint>
  <link name="tablet_tilt_mount_left_link">
    <visual>
      <geometry>
        <box size="0.03 0.03 0.10"/>
      </geometry>
      <origin rpy="0.0 0.0 0.0" xyz="0.0 0.0 0.08"/>
      <material name="white">
        <color rgba="1 1 1 1"/>
      </material>
    </visual>
  </link>
  <joint name="tablet_tilt_mount_right_joint" type="fixed">
    <parent link="tablet_pan_link"/>
    <child link="tablet_tilt_mount_right_link"/>
    <origin rpy="0 0 0" xyz="0 -0.115 0"/>
  </joint>
  <link name="tablet_tilt_mount_right_link">
    <visual>
      <geometry>
        <box size="0.03 0.03 0.10 "/>
      </geometry>
      <origin rpy="0.0 0.0 0.0" xyz="0.0 0.0 0.08"/>
      <material name="white">
        <color rgba="1 1 1 1"/>
      </material>
    </visual>
  </link>
  <joint name="tablet_tilt_joint" type="revolute">
    <parent link="tablet_pan_link"/>
    <child link="tablet_tilt_link"/>
    <origin rpy="1.57079632679 0 0" xyz="0 0 0.13"/>
    <axis xyz="0 0 1"/>
    <limit effort="10" lower="-1.57079632679" upper="1.57079632679" velocity="0.013"/>
  </joint>
  <link name="tablet_tilt_link">
    <visual>
      <geometry>
        <box size="0.01 0.20 0.15"/>
      </geometry>
      <origin rpy="-1.57079632679 0.0 0.0" xyz="0.0 0.0 0.0"/>
      <material name="black">
        <color rgba="0.1 0.1 0.1 1"/>
      </material>
    </visual>
  </link>
  <joint name="asus_tilt_joint" type="fixed">
    <parent link="tablet_tilt_link"/>
    <child link="asus_link"/>
    <origin rpy="0 0 0" xyz="0.0 0.0875 0.0"/>
  </joint>
  <link name="asus_link">
    <visual>
      <geometry>
        <box size="0.025 0.025 0.15"/>
      </geometry>
      <origin rpy="0 0 0" xyz="0.0 0.0 0.0"/>
      <material name="orange">
        <color rgba="1.0 0.7 0.0 1"/>
      </material>
    </visual>
  </link>
  <!-- ************************ Arm model ************************* -->
  <!-- 	<xacro:jaco_arm parent="torso_lift_link"> -->
  <!-- 	</xacro:jaco_arm> -->
  <joint name="jaco_base_joint" type="fixed">
    <origin rpy="-1.57079632679 0 1.57079632679" xyz="-0.14 0 0"/>
    <parent link="torso_lift_link"/>
    <child link="jaco_base_link"/>
  </joint>
  <link name="jaco_base_link">
    <visual>
      <material name="JacoGrey"/>
      <origin rpy="0 0 1.57079632679" xyz="0 0 0"/>
      <geometry>
        <mesh filename="package://jaco_description/meshes/jaco_base_joint.stl"/>
      </geometry>
    </visual>
    <collision>
      <origin rpy="0 0 1.57079632679" xyz="0 0 0"/>
      <geometry>
        <mesh filename="package://jaco_description/meshes/jaco_base_joint.stl"/>
      </geometry>
    </collision>
  </link>
  <joint name="jaco_shoulder_yaw_joint" type="revolute">
    <origin rpy="0 0 0" xyz="0 0 0.2102"/>
    <axis rpy="0 0 0" xyz="0 0 1"/>
    <parent link="jaco_base_link"/>
    <child link="jaco_shoulder_link"/>
    <!--         <limit lower="${-M_PI}" upper="${M_PI}" effort="1" velocity="${M_PI}"/> -->
    <limit effort="10" lower="-9.42477796077" upper="9.42477796077" velocity="0.84"/>
  </joint>
  <link name="jaco_shoulder_link">
    <visual>
      <material name="JacoGrey"/>
      <origin rpy="1.57079632679 -1.57079632679 0" xyz="0 0 0"/>
      <geometry>
        <mesh filename="package://jaco_description/meshes/jaco_shoulder_yaw_joint.stl"/>
      </geometry>
    </visual>
    <collision>
      <origin rpy="1.57079632679 -1.57079632679 0" xyz="0 0 0"/>
      <geometry>
        <mesh filename="package://jaco_description/meshes/jaco_shoulder_yaw_joint.stl"/>
      </geometry>
    </collision>
  </link>
  <joint name="jaco_shoulder_pitch_joint" type="revolute">
    <origin rpy="-1.57079632679 0 0" xyz="0 0 0"/>
    <axis xyz="0 0 1"/>
    <parent link="jaco_shoulder_link"/>
    <child link="jaco_upper_arm_link"/>
    <!--         <limit lower="${-M_PI}" upper="${M_PI}" effort="1" velocity="${M_PI}"/> -->
    <limit effort="10" lower="2.30" upper="7.12" velocity="0.84"/>
  </joint>
  <link name="jaco_upper_arm_link">
    <visual>
      <material name="JacoGrey"/>
      <origin rpy="0 0 -1.57079632679" xyz="0 0 0"/>
      <geometry>
        <mesh filename="package://jaco_description/meshes/jaco_shoulder_pitch_joint.stl"/>
      </geometry>
    </visual>
    <collision>
      <origin rpy="0 0 -1.57079632679" xyz="0 0 0"/>
      <geometry>
        <mesh filename="package://jaco_description/meshes/jaco_shoulder_pitch_joint.stl"/>
      </geometry>
    </collision>
  </link>
  <joint name="jaco_elbow_pitch_joint" type="revolute">
    <origin rpy="0 0 0" xyz="0.41 0 0.012"/>
    <axis xyz="0 0 1"/>
    <parent link="jaco_upper_arm_link"/>
    <child link="jaco_lower_arm_link"/>
    <!--         <limit lower="${-M_PI}" upper="${M_PI}" effort="1" velocity="${M_PI}"/> -->
    <limit effort="10" lower="1.87079632679" upper="7.55398163397" velocity="0.84"/>
  </joint>
  <link name="jaco_lower_arm_link">
    <visual>
      <material name="JacoGrey"/>
      <origin rpy="3.14159265359 0 3.14159265359" xyz="0 0 -0.012"/>
      <geometry>
        <mesh filename="package://jaco_description/meshes/jaco_elbow_pitch_joint.stl"/>
      </geometry>
    </visual>
    <collision>
      <origin rpy="3.14159265359 0 3.14159265359" xyz="0 0 -0.012"/>
      <geometry>
        <mesh filename="package://jaco_description/meshes/jaco_elbow_pitch_joint.stl"/>
      </geometry>
    </collision>
  </link>
  <joint name="jaco_elbow_roll_joint" type="revolute">
    <origin rpy="-1.57079632679 0 0" xyz="0 0.249276823007 0 "/>
    <axis xyz="0 0 1"/>
    <parent link="jaco_lower_arm_link"/>
    <child link="jaco_lower_arm_roll_link"/>
    <!--         <limit lower="${-M_PI}" upper="${M_PI}" effort="1" velocity="${M_PI}"/> -->
    <limit effort="10" lower="-9.42477796077" upper="9.42477796077" velocity="0.84"/>
  </joint>
  <link name="jaco_lower_arm_roll_link">
    <visual>
      <material name="JacoGrey"/>
      <origin rpy="3.14159265359 0 1.57079632679" xyz="0 0 -0.0422768230075"/>
      <geometry>
        <mesh filename="package://jaco_description/meshes/jaco_elbow_roll_joint.stl"/>
      </geometry>
    </visual>
    <collision>
      <origin rpy="3.14159265359 0 1.57079632679" xyz="0 0 -0.0422768230075"/>
      <geometry>
        <mesh filename="package://jaco_description/meshes/jaco_elbow_roll_joint.stl"/>
      </geometry>
    </collision>
  </link>
  <joint name="jaco_wrist_roll_joint" type="revolute">
    <origin rpy="0.959931088597 0 0" xyz="0 -0.0692622919853 0.0484979789618"/>
    <axis xyz="0 0 1"/>
    <parent link="jaco_lower_arm_roll_link"/>
    <child link="jaco_wrist_link"/>
    <!--         <limit lower="${-M_PI}" upper="${M_PI}" effort="1" velocity="${M_PI}"/> -->
    <limit effort="10" lower="-9.42477796077" upper="9.42477796077" velocity="0.84"/>
  </joint>
  <link name="jaco_wrist_link">
    <visual>
      <material name="JacoGrey"/>
      <origin rpy="0 3.14159265359 -1.57079632679" xyz="0 0 -0.0422768230075"/>
      <geometry>
        <mesh filename="package://jaco_description/meshes/jaco_wrist_roll_joint.stl"/>
      </geometry>
    </visual>
    <collision>
      <origin rpy="0 3.14159265359 -1.57079632679" xyz="0 0 -0.0422768230075"/>
      <geometry>
        <mesh filename="package://jaco_description/meshes/jaco_wrist_roll_joint.stl"/>
      </geometry>
    </collision>
  </link>
  <joint name="jaco_hand_roll_joint" type="revolute">
    <origin rpy="0.959931088597 0 0" xyz="0 -0.186174274186 0.130360630206"/>
    <axis xyz="0 0 1"/>
    <parent link="jaco_wrist_link"/>
    <child link="jaco_hand_link"/>
    <!--         <limit lower="${-M_PI}" upper="${M_PI}" effort="1" velocity="${M_PI}"/> -->
    <limit effort="10" lower="-9.42477796077" upper="9.42477796077" velocity="0.84"/>
  </joint>
  <link name="jaco_hand_link">
    <visual>
      <material name="JacoGrey"/>
      <origin rpy="0 0 -3.14159265359" xyz="0 0 -0.185"/>
      <geometry>
        <mesh filename="package://jaco_description/meshes/jaco_hand_roll_joint.stl"/>
      </geometry>
    </visual>
    <collision>
      <origin rpy="0 0 -3.14159265359" xyz="0 0 -0.185"/>
      <geometry>
        <mesh filename="package://jaco_description/meshes/jaco_hand_roll_joint.stl"/>
      </geometry>
    </collision>
  </link>
  <joint name="jaco_finger_1_joint" type="revolute">
    <origin rpy="0 -0.448798950513 0" xyz="-0.036 0.021 -0.07"/>
    <axis xyz="0 1 0"/>
    <parent link="jaco_hand_link"/>
    <child link="jaco_finger_1_link"/>
    <limit effort="1" lower="-3.14159265359" upper="3.14159265359" velocity="3.14159265359"/>
  </joint>
  <link name="jaco_finger_1_link">
    <visual>
      <material name="JacoGrey"/>
      <origin rpy="0 0 0" xyz="0 0 0"/>
      <geometry>
        <mesh filename="package://jaco_description/meshes/finger.dae"/>
      </geometry>
    </visual>
    <collision>
      <origin rpy="0 0 0" xyz="0 0 0"/>
      <geometry>
        <mesh filename="package://jaco_description/meshes/finger.dae"/>
      </geometry>
    </collision>
  </link>
  <joint name="jaco_finger_2_joint" type="revolute">
    <origin rpy="0 -0.448798950513 -3.14159265359" xyz="0.036 -0 -0.07"/>
    <axis xyz="0 1 0"/>
    <parent link="jaco_hand_link"/>
    <child link="jaco_finger_2_link"/>
    <limit effort="1" lower="-3.14159265359" upper="3.14159265359" velocity="3.14159265359"/>
  </joint>
  <link name="jaco_finger_2_link">
    <visual>
      <material name="JacoGrey"/>
      <origin rpy="0 0 0" xyz="0 0 0"/>
      <geometry>
        <mesh filename="package://jaco_description/meshes/finger.dae"/>
      </geometry>
    </visual>
    <collision>
      <origin rpy="0 0 0" xyz="0 0 0"/>
      <geometry>
        <mesh filename="package://jaco_description/meshes/finger.dae"/>
      </geometry>
    </collision>
  </link>
  <joint name="jaco_finger_3_joint" type="revolute">
    <origin rpy="0 -0.448798950513 0" xyz="-0.036 -0.021 -0.07"/>
    <axis xyz="0 1 0"/>
    <parent link="jaco_hand_link"/>
    <child link="jaco_finger_3_link"/>
    <limit effort="1" lower="-3.14159265359" upper="3.14159265359" velocity="3.14159265359"/>
  </joint>
  <link name="jaco_finger_3_link">
    <visual>
      <material name="JacoGrey"/>
      <origin rpy="0 0 0" xyz="0 0 0"/>
      <geometry>
        <mesh filename="package://jaco_description/meshes/finger.dae"/>
      </geometry>
    </visual>
    <collision>
      <origin rpy="0 0 0" xyz="0 0 0"/>
      <geometry>
        <mesh filename="package://jaco_description/meshes/finger.dae"/>
      </geometry>
    </collision>
  </link>
  <!-- ************************ Table model ************************* -->
  <joint name="table_bottom_center_joint" type="fixed">
    <parent link="world"/>
    <child link="table_bottom_center_link"/>
    <origin rpy="0 0 0" xyz="1.00 0.0 0"/>
  </joint>
  <link name="table_bottom_center_link">
	  </link>
  <joint name="table_foot_front_right_bottom_joint" type="fixed">
    <parent link="table_bottom_center_link"/>
    <child link="table_foot_front_right_bottom_link"/>
    <origin rpy="0 0 0" xyz="0.4 0.3 0.0"/>
  </joint>
  <link name="table_foot_front_right_bottom_link">
    <visual>
      <origin rpy="0 0 0" xyz="0.0 0 0.20"/>
      <geometry>
        <cylinder length="0.40" radius="0.02"/>
      </geometry>
      <material name="black">
        <color rgba="0.7 0.1 0.1 1"/>
      </material>
    </visual>
    <collision>
      <origin rpy="0 0 0" xyz="0.0 0 0.20"/>
      <geometry>
        <cylinder length="0.40" radius="0.02"/>
      </geometry>
    </collision>
  </link>
  <joint name="table_foot_front_right_top_joint" type="prismatic">
    <parent link="table_foot_front_right_bottom_link"/>
    <child link="table_foot_front_right_link"/>
    <origin rpy="0 0 0" xyz="0 0 0.4"/>
    <axis xyz="0 0 1"/>
    <limit effort="10" lower="-0.4" upper="0.0" velocity="0.4"/>
  </joint>
  <link name="table_foot_front_right_link">
    <visual>
      <origin rpy="0 0 0" xyz="0.0 0 0.20"/>
      <geometry>
        <cylinder length="0.40" radius="0.02"/>
      </geometry>
      <material name="black">
        <color rgba="0.7 0.1 0.1 1"/>
      </material>
    </visual>
    <collision>
      <origin rpy="0 0 0" xyz="0.0 0 0.20"/>
      <geometry>
        <cylinder length="0.40" radius="0.02"/>
      </geometry>
    </collision>
  </link>
  <joint name="table_foot_front_left_joint" type="fixed">
    <parent link="table_bottom_center_link"/>
    <child link="table_foot_front_left_link"/>
    <origin rpy="0 0 0" xyz="0.4 -0.3 0"/>
  </joint>
  <link name="table_foot_front_left_link">
    <visual>
      <origin rpy="0 0 0" xyz="0.0 0 0.375"/>
      <geometry>
        <cylinder length="0.75" radius="0.02"/>
      </geometry>
      <material name="black">
        <color rgba="0.7 0.1 0.1 1"/>
      </material>
    </visual>
    <collision>
      <origin rpy="0 0 0" xyz="0.0 0 0.375"/>
      <geometry>
        <cylinder length="0.75" radius="0.02"/>
      </geometry>
    </collision>
  </link>
  <joint name="table_foot_back_right_joint" type="fixed">
    <parent link="table_bottom_center_link"/>
    <child link="table_foot_back_right_link"/>
    <origin rpy="0 0 0" xyz="-0.4 0.3 0"/>
  </joint>
  <link name="table_foot_back_right_link">
    <visual>
      <geometry>
        <cylinder length="0.75" radius="0.02"/>
      </geometry>
      <origin rpy="0 0 0" xyz="0.0 0 0.375"/>
      <material name="black">
        <color rgba="0.7 0.1 0.1 1"/>
      </material>
    </visual>
    <collision>
      <geometry>
        <cylinder length="0.75" radius="0.02"/>
      </geometry>
      <origin rpy="0 0 0" xyz="0.0 0 0.375"/>
    </collision>
  </link>
  <joint name="table_foot_back_left_joint" type="fixed">
    <parent link="table_bottom_center_link"/>
    <child link="table_foot_back_left_link"/>
    <origin rpy="0 0 0" xyz="-0.4 -0.3 0"/>
  </joint>
  <link name="table_foot_back_left_link">
    <visual>
      <geometry>
        <cylinder length="0.75" radius="0.02"/>
      </geometry>
      <origin rpy="0 0 0" xyz="0.0 0 0.375"/>
      <material name="black">
        <color rgba="0.7 0.1 0.1 1"/>
      </material>
    </visual>
    <collision>
      <geometry>
        <cylinder length="0.75" radius="0.02"/>
      </geometry>
      <origin rpy="0 0 0" xyz="0.0 0 0.375"/>
    </collision>
  </link>
  <joint name="table_top_center_joint" type="prismatic">
    <parent link="table_bottom_center_link"/>
    <child link="table_top_center_link"/>
    <origin rpy="0 0 0" xyz="0.0 0.0 0.80"/>
    <axis xyz="0 0 1"/>
    <limit effort="10" lower="-0.4" upper="0.0" velocity="0.4"/>
  </joint>
  <link name="table_top_center_link">
    <visual>
      <geometry>
        <box size="0.90 0.70 0.05"/>
      </geometry>
      <origin rpy="0 0.0 0" xyz="0.0 0.0 -0.025"/>
      <material name="black">
        <color rgba="0.7 0.1 0.1 1"/>
      </material>
    </visual>
    <collision>
      <geometry>
        <box size="0.90 0.70 0.05"/>
      </geometry>
      <origin rpy="0 0.0 0" xyz="0.0 0.0 -0.025"/>
    </collision>
  </link>
</robot>

