<?xml version="1.0" ?>
<!-- =================================================================================== -->
<!-- |    This document was autogenerated by xacro from korus_v3_world.urdf.xacro      | -->
<!-- |    EDITING THIS FILE BY HAND IS NOT RECOMMENDED                                 | -->
<!-- =================================================================================== -->
<robot name="korus_v3" xmlns:xacro="http://www.ros.org/wiki/xacro">
  <!--   <include filename="$(find korus_meta)/resources/urdf/omni_drive_base.urdf.xacro"/> -->
  <!-- ************************ Base model ************************* -->
  <link name="local_manip_start"/>
  <joint name="base_position_x_joint" type="prismatic">
    <parent link="local_manip_start"/>
    <child link="base_position_x_link"/>
    <origin rpy="0 0 0" xyz="0.0 0.0 0.0"/>
    <axis xyz="1 0 0"/>
    <limit effort="10" lower="-2.0" upper="2.0" velocity="1.0"/>
  </joint>
  <link name="base_position_x_link"/>
  <joint name="base_position_y_joint" type="prismatic">
    <parent link="base_position_x_link"/>
    <child link="base_position_y_link"/>
    <origin rpy="0 0 0" xyz="0.0 0.0 0.0"/>
    <axis xyz="0 1 0"/>
    <limit effort="10" lower="-2.0" upper="2.0" velocity="1.0"/>
  </joint>
  <link name="base_position_y_link"/>
  <joint name="base_heading_joint" type="revolute">
    <parent link="base_position_y_link"/>
    <child link="base_link"/>
    <origin rpy="0 0 0" xyz="0.0 0.0 0.075"/>
    <axis xyz="0 0 1"/>
    <limit effort="10" lower="-3.14159265359" upper="3.14159265359" velocity="1.0"/>
  </joint>
  <link name="base_link">
    <visual>
      <origin rpy="0 0 0" xyz="0.0 0 0.0875"/>
      <geometry>
        <cylinder length="0.275" radius="0.250"/>
      </geometry>
      <material name="white">
        <color rgba="1 1 1 1"/>
      </material>
    </visual>
    <collision>
      <origin rpy="0 0 0" xyz="0.0 0 0.0875"/>
      <geometry>
        <cylinder length="0.275" radius="0.250"/>
      </geometry>
      <material name="white">
        <color rgba="1 1 1 1"/>
      </material>
    </collision>
  </link>
  <joint name="wheel_left_joint" type="fixed">
    <parent link="base_link"/>
    <child link="wheel_left_link"/>
    <origin rpy="0 0 1.57079632679" xyz="0.0 0.15 0.0"/>
  </joint>
  <link name="wheel_left_link">
    <visual>
      <geometry>
        <cylinder length="0.03" radius="0.075"/>
      </geometry>
      <origin rpy="0 1.57079632679 0" xyz="0 0 0"/>
      <material name="black">
        <color rgba="0.1 0.1 0.1 1"/>
      </material>
    </visual>
  </link>
  <joint name="wheel_right_joint" type="fixed">
    <parent link="base_link"/>
    <child link="wheel_right_link"/>
    <origin rpy="0 0 1.57079632679" xyz="0.0 -0.15 0.0"/>
  </joint>
  <link name="wheel_right_link">
    <visual>
      <geometry>
        <cylinder length="0.03" radius="0.075"/>
      </geometry>
      <origin rpy="0 1.57079632679 0" xyz="0 0 0"/>
      <material name="black">
        <color rgba="0.1 0.1 0.1 1"/>
      </material>
    </visual>
  </link>
  <joint name="caster_front_left_joint" type="fixed">
    <parent link="base_link"/>
    <child link="caster_front_left_link"/>
    <origin rpy="0 0 1.57079632679" xyz="0.18 0.1 -0.035"/>
  </joint>
  <link name="caster_front_left_link">
    <visual>
      <geometry>
        <cylinder length="0.02" radius="0.04"/>
      </geometry>
      <origin rpy="0 1.57079632679 0" xyz="0 0 0"/>
      <material name="black">
        <color rgba="0.1 0.1 0.1 1"/>
      </material>
    </visual>
  </link>
  <joint name="caster_front_right_joint" type="fixed">
    <parent link="base_link"/>
    <child link="caster_front_right_link"/>
    <origin rpy="0 0 1.57079632679" xyz="0.18 -0.1 -0.035"/>
  </joint>
  <link name="caster_front_right_link">
    <visual>
      <geometry>
        <cylinder length="0.02" radius="0.04"/>
      </geometry>
      <origin rpy="0 1.57079632679 0" xyz="0 0 0"/>
      <material name="black">
        <color rgba="0.1 0.1 0.1 1"/>
      </material>
    </visual>
  </link>
  <joint name="caster_back_left_joint" type="fixed">
    <parent link="base_link"/>
    <child link="caster_back_left_link"/>
    <origin rpy="0 0 1.57079632679" xyz="-0.18 0.1 -0.035"/>
  </joint>
  <link name="caster_back_left_link">
    <visual>
      <geometry>
        <cylinder length="0.02" radius="0.04"/>
      </geometry>
      <origin rpy="0 1.57079632679 0" xyz="0 0 0"/>
      <material name="black">
        <color rgba="0.1 0.1 0.1 1"/>
      </material>
    </visual>
  </link>
  <joint name="caster_back_right_joint" type="fixed">
    <parent link="base_link"/>
    <child link="caster_back_right_link"/>
    <origin rpy="0 0 1.57079632679" xyz="-0.18 -0.1 -0.035"/>
  </joint>
  <link name="caster_back_right_link">
    <visual>
      <geometry>
        <cylinder length="0.02" radius="0.04"/>
      </geometry>
      <origin rpy="0 1.57079632679 0" xyz="0 0 0"/>
      <material name="black">
        <color rgba="0.1 0.1 0.1 1"/>
      </material>
    </visual>
  </link>
  <!--   <xacro:diff_drive_base parent="base_footprint" body_mount_link="base_link"/> -->
  <!--   <xacro:omni_drive_base parent="base_footprint" body_mount_link="base_link"/> -->
  <!-- ************************ Body model ************************* -->
  <joint name="torso_joint" type="revolute">
    <parent link="base_link"/>
    <child link="torso_link"/>
    <origin rpy="0 0 0" xyz="0.0 0.0 0.250"/>
    <axis xyz="0 0 1"/>
    <limit effort="10" lower="-3.14159265359" upper="2.79252680319" velocity="1.0"/>
  </joint>
  <link name="torso_link">
    <visual>
      <origin rpy="0 0 0" xyz="0.0 0.0 0.0"/>
      <geometry>
        <cylinder length="0.05" radius="0.25"/>
      </geometry>
      <material name="white">
        <color rgba="1 1 1 1"/>
      </material>
    </visual>
    <collision>
      <origin rpy="0 0 0" xyz="0.0 0.0 0.0"/>
      <geometry>
        <cylinder length="0.05" radius="0.25"/>
      </geometry>
      <material name="white">
        <color rgba="1 1 1 1"/>
      </material>
    </collision>
  </link>
  <joint name="turret_offset_joint" type="fixed">
    <parent link="torso_link"/>
    <child link="turret_offset_link"/>
    <origin rpy="0 0 0" xyz="-0.155 0.0 0.025"/>
  </joint>
  <link name="turret_offset_link">
    <visual>
      <geometry>
        <box size="0.15 0.20 0.5"/>
      </geometry>
      <origin rpy="0 0 0" xyz="0.0 0 0.25"/>
      <material name="white">
        <color rgba="1 1 1 1"/>
      </material>
    </visual>
    <collision>
      <geometry>
        <box size="0.15 0.20 0.5"/>
      </geometry>
      <origin rpy="0 0 0" xyz="0 0 0.25"/>
    </collision>
  </link>
  <joint name="torso_lift_offset" type="fixed">
    <parent link="turret_offset_link"/>
    <child link="torso_lift_offset_link"/>
    <origin rpy="0 0 0" xyz="0 0 0.22"/>
  </joint>
  <link name="torso_lift_offset_link"/>
  <joint name="torso_lift" type="prismatic">
    <parent link="torso_lift_offset_link"/>
    <child link="torso_lift_link"/>
    <origin rpy="0 0 3.14159265359" xyz="0 0 0"/>
    <axis xyz="0 0 1"/>
    <limit effort="10" lower="-0.07" upper="0.13" velocity="0.5"/>
  </joint>
  <link name="torso_lift_link"/>
  <joint name="neck_joint" type="fixed">
    <parent link="turret_offset_link"/>
    <child link="neck_link"/>
    <origin rpy="0 0 0" xyz="0.0 0.0 0.5"/>
  </joint>
  <link name="neck_link">
    <visual>
      <geometry>
        <box size="0.04 0.04 0.30"/>
      </geometry>
      <origin rpy="0 0 0" xyz="0.0 0.0 0.15"/>
      <material name="white">
        <color rgba="1 1 1 1"/>
      </material>
    </visual>
    <collision>
      <geometry>
        <box size="0.04 0.04 0.30"/>
      </geometry>
      <origin rpy="0 0 0" xyz="0.0 0.0 0.15"/>
      <material name="white">
        <color rgba="1 1 1 1"/>
      </material>
    </collision>
  </link>
  <joint name="tablet_joint" type="fixed">
    <parent link="neck_link"/>
    <child link="tablet_link"/>
    <origin rpy="0 0 0" xyz="0.02 0.0 0.15"/>
  </joint>
  <link name="tablet_link">
    <visual>
      <geometry>
        <box size="0.015 0.270 0.175"/>
      </geometry>
      <origin rpy="0.0 -0.5 0.0" xyz="0.05 0.0 0.0"/>
      <material name="black">
        <color rgba="0.1 0.1 0.1 1"/>
      </material>
    </visual>
    <collision>
      <geometry>
        <box size="0.015 0.270 0.175"/>
      </geometry>
      <origin rpy="0.0 -0.5 0.0" xyz="0.05 0.0 0.0"/>
      <material name="black">
        <color rgba="0.1 0.1 0.1 1"/>
      </material>
    </collision>
  </link>
  <joint name="head_joint" type="fixed">
    <parent link="neck_link"/>
    <child link="head_link"/>
    <origin rpy="0 0 0" xyz="0.0 0.0 0.3"/>
  </joint>
  <link name="head_link">
    <visual>
      <geometry>
        <box size="0.20 0.04 0.04"/>
      </geometry>
      <origin rpy="0.0 0.0 0.0" xyz="0.02 0.0 0.02"/>
      <material name="white">
        <color rgba="1 1 1 1"/>
      </material>
    </visual>
    <collision>
      <geometry>
        <box size="0.20 0.04 0.04"/>
      </geometry>
      <origin rpy="0.0 0.0 0.0" xyz="0.02 0.0 0.02"/>
      <material name="white">
        <color rgba="1 1 1 1"/>
      </material>
    </collision>
  </link>
  <joint name="asus_pan_joint" type="revolute">
    <parent link="head_link"/>
    <child link="asus_pan_link"/>
    <origin rpy="0 0 0" xyz="0.10 0.0 0.04"/>
    <axis xyz="0 0 1"/>
    <limit effort="10" lower="-2.35619449019" upper="2.35619449019" velocity="1.0"/>
  </joint>
  <link name="asus_pan_link">
    <visual>
      <geometry>
        <box size="0.04 0.04 0.04"/>
      </geometry>
      <origin rpy="0.0 0.0 0.0" xyz="0.0 0.0 0.02"/>
      <material name="white">
        <color rgba="1 1 1 1"/>
      </material>
    </visual>
    <collision>
      <geometry>
        <box size="0.04 0.04 0.04"/>
      </geometry>
      <origin rpy="0.0 0.0 0.0" xyz="0.0 0.0 0.02"/>
      <material name="white">
        <color rgba="1 1 1 1"/>
      </material>
    </collision>
  </link>
  <joint name="asus_tilt_joint" type="revolute">
    <parent link="asus_pan_link"/>
    <child link="asus_tilt_link"/>
    <origin rpy="-1.57079632679 0 0" xyz="0.02 0.0 0.02"/>
    <axis xyz="0 0 1"/>
    <limit effort="10" lower="-1.57079632679" upper="0.523598775598" velocity="1.0"/>
  </joint>
  <link name="asus_tilt_link">
    <visual>
      <geometry>
        <box size="0.05 0.035 0.18"/>
      </geometry>
      <origin rpy="0 0 0" xyz="0.025 0.0 0.0"/>
      <material name="orange">
        <color rgba="1.0 0.7 0.0 1"/>
      </material>
    </visual>
    <collision>
      <geometry>
        <box size="0.05 0.035 0.18"/>
      </geometry>
      <origin rpy="0 0 0" xyz="0.025 0.0 0.0"/>
      <material name="orange">
        <color rgba="1.0 0.7 0.0 1"/>
      </material>
    </collision>
  </link>
  <joint name="stargazer_joint" type="fixed">
    <parent link="head_link"/>
    <child link="stargazer_link"/>
    <origin rpy="0 0 0" xyz="-0.05 0.0 0.04"/>
  </joint>
  <link name="stargazer_link">
    <visual>
      <geometry>
        <box size="0.07 0.07 0.05"/>
      </geometry>
      <origin rpy="0.0 0.0 0.0" xyz="0.0 0.0 0.025"/>
      <material name="orange">
        <color rgba="1.0 0.7 0.0 1"/>
      </material>
    </visual>
    <collision>
      <geometry>
        <box size="0.07 0.07 0.05"/>
      </geometry>
      <origin rpy="0.0 0.0 0.0" xyz="0.0 0.0 0.025"/>
      <material name="orange">
        <color rgba="1.0 0.7 0.0 1"/>
      </material>
    </collision>
  </link>
  <!-- ************************ Arm model ************************* -->
  <joint name="arm_mount_joint" type="fixed">
    <parent link="torso_lift_link"/>
    <child link="shoulder_link"/>
    <origin rpy="0 0 0" xyz="-0.075 -0.06 0"/>
  </joint>
  <link name="shoulder_link">
    <visual>
      <geometry>
        <box size="0.14 0.12 0.26"/>
      </geometry>
      <origin rpy="0 0 0" xyz="-0.07 0.0 0.0"/>
      <material name="grey_blue">
        <color rgba="0.4 0.4 1.0 1"/>
      </material>
    </visual>
  </link>
  <joint name="shoulder_joint" type="revolute">
    <parent link="shoulder_link"/>
    <child link="upper_arm_link"/>
    <origin rpy="-1.57079632679 -1.57079632679 0.0" xyz="-0.08 0.06 -0.08"/>
    <axis xyz="0 0 1"/>
    <limit effort="10" lower="-4.71238898038" upper="0.0" velocity="0.013"/>
  </joint>
  <link name="upper_arm_link">
    <visual>
      <geometry>
        <box size="0.41 0.10 0.06"/>
      </geometry>
      <origin rpy="0 0 0" xyz="0.155 0.0 0.03"/>
      <material name="grey_blue">
        <color rgba="0.4 0.4 1.0 1"/>
      </material>
    </visual>
  </link>
  <joint name="elbow_joint" type="revolute">
    <parent link="upper_arm_link"/>
    <child link="lower_arm_link"/>
    <origin rpy="0 0 3.141592" xyz="0.31 0.0 0.06"/>
    <axis xyz="0 0 1"/>
    <limit effort="10" lower="0.0" upper="4.71238898038" velocity="0.013"/>
  </joint>
  <link name="lower_arm_link">
    <visual>
      <geometry>
        <box size="0.48 0.10 0.06"/>
      </geometry>
      <origin rpy="0 0 0" xyz="0.19 0.00 0.03"/>
      <material name="grey_blue">
        <color rgba="0.4 0.4 1.0 1"/>
      </material>
    </visual>
  </link>
  <joint name="wrist_joint" type="revolute">
    <parent link="lower_arm_link"/>
    <child link="wrist_link"/>
    <origin rpy="0 0 1.57079632679" xyz="0.40 0.0 0.0"/>
    <axis xyz="0 0 1"/>
    <limit effort="10" lower="-3.14159265359" upper="3.14159265359" velocity="0.013"/>
  </joint>
  <link name="wrist_link">
    <visual>
      <geometry>
        <cylinder length="0.06" radius="0.03"/>
      </geometry>
      <origin rpy="0 0 0" xyz="0.0 0.0 -0.03"/>
      <material name="grey_blue">
        <color rgba="0.4 0.4 1.0 1"/>
      </material>
    </visual>
  </link>
  <joint name="gripper_joint" type="fixed">
    <parent link="wrist_link"/>
    <child link="gripper_link"/>
    <origin rpy="0.0 0.0 0.0" xyz="0.05 0 -0.06"/>
    <axis xyz="0 0 1"/>
    <limit effort="10" lower="-1.6232" upper="1.6232" velocity="0.5"/>
  </joint>
  <link name="gripper_link">
    <visual>
      <geometry>
        <box size="0.04 0.04 0.12"/>
      </geometry>
      <origin rpy="0 0 0" xyz="0.0 0.0 0.0"/>
      <material name="grey_blue">
        <color rgba="0.4 0.4 1.0 1"/>
      </material>
    </visual>
  </link>
  <joint name="gripper_left_finger_joint" type="prismatic">
    <parent link="gripper_link"/>
    <child link="gripper_left_finger_tip_link"/>
    <origin rpy="0.0 0.0 0.0" xyz="0.02 0.0 -0.05"/>
    <axis xyz="0 1 0"/>
    <limit effort="10" lower="0.0" upper="0.04" velocity="0.5"/>
  </joint>
  <link name="gripper_left_finger_tip_link">
    <visual>
      <geometry>
        <box size="0.08 0.03 0.02"/>
      </geometry>
      <origin rpy="0 0 0" xyz="0.04 0.0 0.0"/>
      <material name="grey_blue">
        <color rgba="0.4 0.4 1.0 1"/>
      </material>
    </visual>
  </link>
  <joint name="gripper_right_finger_joint" type="prismatic">
    <parent link="gripper_link"/>
    <child link="gripper_right_finger_tip_link"/>
    <origin rpy="3.14159265359 0.0 0.0" xyz="0.02 0.0 0.05"/>
    <axis xyz="0 1 0"/>
    <limit effort="10" lower="0.0" upper="0.04" velocity="0.5"/>
  </joint>
  <link name="gripper_right_finger_tip_link">
    <visual>
      <geometry>
        <box size="0.08 0.03 0.02"/>
      </geometry>
      <origin rpy="0 0 0" xyz="0.04 0.0 0.0"/>
      <material name="grey_blue">
        <color rgba="0.4 0.4 1.0 1"/>
      </material>
    </visual>
  </link>
  <joint name="gripper_center_joint" type="fixed">
    <parent link="gripper_link"/>
    <child link="gripper_center_link"/>
    <origin rpy="0 0 0" xyz="0.10 0 0"/>
  </joint>
  <link name="gripper_center_link">
    <!--       <visual> -->
    <!--         <geometry> -->
    <!--           <box size="0.10 0.15 0.10"/> -->
    <!--         </geometry> -->
    <!--         <origin xyz="0.0 0.0 0.0" rpy="0 0 0"/> -->
    <!--         <xacro:insert_block name="material_orange" /> -->
    <!--       </visual>    -->
  </link>
  <!-- ************************ Table model ************************* -->
  <!--   <xacro:table parent="world"/> -->
  <!-- ************************ Object on floor ************************* -->
  <!--   <joint name="floor_object" type="fixed"> -->
  <!--     <parent link="world"/> -->
  <!--     <child link="floor_object_link"/> -->
  <!--     <origin xyz="-0.3 0.0 0.0" rpy="0 0 0" /> -->
  <!--   </joint> -->
  <!-- 	<link name="floor_object_link"> -->
  <!-- 	  <visual> -->
  <!-- 	    <geometry> -->
  <!-- 	      <box size="0.08 0.08 0.15"/> -->
  <!-- 	    </geometry> -->
  <!-- 	    <origin xyz="0.0 0.0 0.075" rpy="0 0 0"/> -->
  <!-- 	    <xacro:insert_block name="material_green" /> -->
  <!-- 	  </visual> -->
  <!-- 	  <collision> -->
  <!-- 	    <geometry> -->
  <!-- 	      <box size="0.08 0.08 0.15"/> -->
  <!-- 	    </geometry> -->
  <!-- 	    <origin xyz="0.0 0.0 0.075" rpy="0 0 0"/> -->
  <!-- 	    <xacro:insert_block name="material_green" />   -->
  <!-- 	  </collision> -->
  <!-- 	</link> -->
</robot>
