<?xml version="1.0" ?>
<!-- =================================================================================== -->
<!-- |    This document was autogenerated by xacro from korus_v3_diff_drive.urdf.xacro | -->
<!-- |    EDITING THIS FILE BY HAND IS NOT RECOMMENDED                                 | -->
<!-- =================================================================================== -->
<robot name="korus_v3" xmlns:controller="http://playerstage.sourceforge.net/gazebo/xmlschema/#controller" xmlns:interface="http://playerstage.sourceforge.net/gazebo/xmlschema/#interface" xmlns:sensor="http://playerstage.sourceforge.net/gazebo/xmlschema/#sensor" xmlns:xacro="http://www.ros.org/wiki/xacro">
  <joint name="laser_joint" type="fixed">
    <axis xyz="0 1 0"/>
    <origin rpy="0 0 0" xyz="0.25 0.0 0.25"/>
    <parent link="base_link"/>
    <child link="laser_link"/>
  </joint>
  <link name="laser_link" type="laser">
    <inertial>
      <mass value="0.001"/>
      <origin rpy="0 0 0" xyz="0 0 0"/>
      <inertia ixx="0.0001" ixy="0" ixz="0" iyy="0.000001" iyz="0" izz="0.0001"/>
    </inertial>
    <visual>
      <geometry>
        <cylinder length="0.07" radius="0.025"/>
      </geometry>
      <origin rpy="0 0 0" xyz="0.0 0.0 -0.02"/>
      <material name="orange">
        <color rgba="1.0 0.7 0.0 1"/>
      </material>
    </visual>
    <collision>
      <geometry>
        <cylinder length="0.07" radius="0.025"/>
      </geometry>
      <origin rpy="0 0 0" xyz="0.0 0.0 -0.02"/>
    </collision>
  </link>
  <gazebo reference="laser_link">
    <sensor:ray name="laser">
      <rayCount>640</rayCount>
      <rangeCount>640</rangeCount>
      <laserCount>1</laserCount>
      <origin>0.0 0.0 0.0</origin>
      <displayRays>false</displayRays>
      <minAngle>-89.9999999997</minAngle>
      <maxAngle>89.9999999997</maxAngle>
      <minRange>0.08</minRange>
      <maxRange>10.0</maxRange>
      <resRange>0.01</resRange>
      <updateRate>20</updateRate>
      <controller:gazebo_ros_laser name="gazebo_ros_laser_controller" plugin="libgazebo_ros_laser.so">
        <gaussianNoise>0.005</gaussianNoise>
        <alwaysOn>true</alwaysOn>
        <updateRate>20</updateRate>
        <topicName>laser_scan</topicName>
        <frameName>laser_link</frameName>
        <interface:laser name="gazebo_ros_laser_iface"/>
      </controller:gazebo_ros_laser>
    </sensor:ray>
    <material>Gazebo/Gold</material>
    <!--  Physics necessary? -->
    <mu1>50.0</mu1>
    <mu2>50.0</mu2>
    <kp>1000000.0</kp>
    <kd>1.0</kd>
  </gazebo>
  <!-- ************************ Base model ************************* -->
  <link name="base_footprint"/>
  <joint name="base_joint" type="fixed">
    <parent link="base_footprint"/>
    <child link="base_link"/>
    <origin rpy="0 0 0" xyz="0.0 0.0 0.075"/>
  </joint>
  <link name="base_link">
    <visual>
      <origin rpy="0 0 0" xyz="0.0 0 0.0875"/>
      <geometry>
        <cylinder length="0.275" radius="0.280"/>
      </geometry>
      <material name="white">
        <color rgba="1 1 1 1"/>
      </material>
    </visual>
    <collision>
      <origin rpy="0 0 0" xyz="0.0 0 0.0875"/>
      <geometry>
        <cylinder length="0.275" radius="0.280"/>
      </geometry>
      <material name="white">
        <color rgba="1 1 1 1"/>
      </material>
    </collision>
  </link>
  <joint name="wheel_left" type="continuous">
    <parent link="base_link"/>
    <child link="wheel_left_link"/>
    <origin rpy="0 0 1.57079632679" xyz="0.0 0.225 0.0"/>
    <limit effort="48.0" velocity="0.5"/>
  </joint>
  <link name="wheel_left_link">
    <visual>
      <geometry>
        <cylinder length="0.03" radius="0.075"/>
      </geometry>
      <origin rpy="0 1.57079632679 0" xyz="0 0 0"/>
      <material name="black">
        <color rgba="0.1 0.1 0.1 1"/>
      </material>
    </visual>
  </link>
  <joint name="wheel_right" type="continuous">
    <parent link="base_link"/>
    <child link="wheel_right_link"/>
    <origin rpy="0 0 1.57079632679" xyz="0.0 -0.225 0.0"/>
    <limit effort="48.0" velocity="0.5"/>
  </joint>
  <link name="wheel_right_link">
    <visual>
      <geometry>
        <cylinder length="0.03" radius="0.075"/>
      </geometry>
      <origin rpy="0 1.57079632679 0" xyz="0 0 0"/>
      <material name="black">
        <color rgba="0.1 0.1 0.1 1"/>
      </material>
    </visual>
  </link>
  <joint name="caster_front_left_joint" type="fixed">
    <parent link="base_link"/>
    <child link="caster_front_left_link"/>
    <origin rpy="0 0 1.57079632679" xyz="0.18 0.1 -0.035"/>
  </joint>
  <link name="caster_front_left_link">
    <visual>
      <geometry>
        <cylinder length="0.02" radius="0.04"/>
      </geometry>
      <origin rpy="0 1.57079632679 0" xyz="0 0 0"/>
      <material name="black">
        <color rgba="0.1 0.1 0.1 1"/>
      </material>
    </visual>
  </link>
  <joint name="caster_front_right_joint" type="fixed">
    <parent link="base_link"/>
    <child link="caster_front_right_link"/>
    <origin rpy="0 0 1.57079632679" xyz="0.18 -0.1 -0.035"/>
  </joint>
  <link name="caster_front_right_link">
    <visual>
      <geometry>
        <cylinder length="0.02" radius="0.04"/>
      </geometry>
      <origin rpy="0 1.57079632679 0" xyz="0 0 0"/>
      <material name="black">
        <color rgba="0.1 0.1 0.1 1"/>
      </material>
    </visual>
  </link>
  <joint name="caster_back_left_joint" type="fixed">
    <parent link="base_link"/>
    <child link="caster_back_left_link"/>
    <origin rpy="0 0 1.57079632679" xyz="-0.18 0.1 -0.035"/>
  </joint>
  <link name="caster_back_left_link">
    <visual>
      <geometry>
        <cylinder length="0.02" radius="0.04"/>
      </geometry>
      <origin rpy="0 1.57079632679 0" xyz="0 0 0"/>
      <material name="black">
        <color rgba="0.1 0.1 0.1 1"/>
      </material>
    </visual>
  </link>
  <joint name="caster_back_right_joint" type="fixed">
    <parent link="base_link"/>
    <child link="caster_back_right_link"/>
    <origin rpy="0 0 1.57079632679" xyz="-0.18 -0.1 -0.035"/>
  </joint>
  <link name="caster_back_right_link">
    <visual>
      <geometry>
        <cylinder length="0.02" radius="0.04"/>
      </geometry>
      <origin rpy="0 1.57079632679 0" xyz="0 0 0"/>
      <material name="black">
        <color rgba="0.1 0.1 0.1 1"/>
      </material>
    </visual>
  </link>
  <!-- ************************ Body model ************************* -->
  <joint name="torso_turn" type="revolute">
    <parent link="base_link"/>
    <child link="torso_link"/>
    <origin rpy="0 0 0" xyz="0.0 0.0 0.250"/>
    <axis xyz="0 0 1"/>
    <limit effort="205.0" lower="-3.2463124087" upper="2.79252680318" velocity="1.54810704652"/>
  </joint>
  <link name="torso_link">
    <visual>
      <origin rpy="0 0 0" xyz="0.0 0.0 0.0"/>
      <geometry>
        <cylinder length="0.050" radius="0.280"/>
      </geometry>
      <material name="white">
        <color rgba="1 1 1 1"/>
      </material>
    </visual>
    <collision>
      <origin rpy="0 0 0" xyz="0.0 0.0 0.0"/>
      <geometry>
        <cylinder length="0.050" radius="0.280"/>
      </geometry>
      <material name="white">
        <color rgba="1 1 1 1"/>
      </material>
    </collision>
  </link>
  <joint name="turret_offset" type="fixed">
    <parent link="torso_link"/>
    <child link="turret_offset_link"/>
    <origin rpy="0 0 0" xyz="-0.155 0.0 0.025"/>
  </joint>
  <link name="turret_offset_link">
    <visual>
      <geometry>
        <box size="0.15 0.20 0.5"/>
      </geometry>
      <origin rpy="0 0 0" xyz="0.0 0 0.25"/>
      <material name="white">
        <color rgba="1 1 1 1"/>
      </material>
    </visual>
    <collision>
      <geometry>
        <box size="0.15 0.20 0.5"/>
      </geometry>
      <origin rpy="0 0 0" xyz="0 0 0.25"/>
    </collision>
  </link>
  <joint name="torso_lift_offset" type="fixed">
    <parent link="turret_offset_link"/>
    <child link="torso_lift_offset_link"/>
    <origin rpy="0 0 0" xyz="0 0 0.22"/>
  </joint>
  <link name="torso_lift_offset_link"/>
  <joint name="torso_lift" type="prismatic">
    <parent link="torso_lift_offset_link"/>
    <child link="torso_lift_link"/>
    <origin rpy="0 0 3.14159265359" xyz="0 0 0"/>
    <axis xyz="0 0 1"/>
    <!-- 	    <limit lower="-0.07" upper="0.13" velocity="0.5"/> -->
    <limit effort="26.0" lower="0.0" upper="0.180" velocity="0.038"/>
  </joint>
  <link name="torso_lift_link"/>
  <joint name="neck" type="fixed">
    <parent link="turret_offset_link"/>
    <child link="neck_link"/>
    <origin rpy="0 0 0" xyz="0.0 0.0 0.5"/>
  </joint>
  <link name="neck_link">
    <visual>
      <geometry>
        <box size="0.04 0.04 0.30"/>
      </geometry>
      <origin rpy="0 0 0" xyz="0.0 0.0 0.15"/>
      <material name="white">
        <color rgba="1 1 1 1"/>
      </material>
    </visual>
    <collision>
      <geometry>
        <box size="0.04 0.04 0.30"/>
      </geometry>
      <origin rpy="0 0 0" xyz="0.0 0.0 0.15"/>
      <material name="white">
        <color rgba="1 1 1 1"/>
      </material>
    </collision>
  </link>
  <joint name="tablet" type="fixed">
    <parent link="neck_link"/>
    <child link="tablet_link"/>
    <origin rpy="0 0 0" xyz="0.02 0.0 0.15"/>
  </joint>
  <link name="tablet_link">
    <visual>
      <geometry>
        <box size="0.015 0.270 0.175"/>
      </geometry>
      <origin rpy="0.0 -0.5 0.0" xyz="0.05 0.0 0.0"/>
      <material name="black">
        <color rgba="0.1 0.1 0.1 1"/>
      </material>
    </visual>
    <collision>
      <geometry>
        <box size="0.015 0.270 0.175"/>
      </geometry>
      <origin rpy="0.0 -0.5 0.0" xyz="0.05 0.0 0.0"/>
      <material name="black">
        <color rgba="0.1 0.1 0.1 1"/>
      </material>
    </collision>
  </link>
  <joint name="head" type="fixed">
    <parent link="neck_link"/>
    <child link="head_link"/>
    <origin rpy="0 0 0" xyz="0.0 0.0 0.3"/>
  </joint>
  <link name="head_link">
    <visual>
      <geometry>
        <box size="0.20 0.04 0.04"/>
      </geometry>
      <origin rpy="0.0 0.0 0.0" xyz="0.02 0.0 0.02"/>
      <material name="white">
        <color rgba="1 1 1 1"/>
      </material>
    </visual>
    <collision>
      <geometry>
        <box size="0.20 0.04 0.04"/>
      </geometry>
      <origin rpy="0.0 0.0 0.0" xyz="0.02 0.0 0.02"/>
      <material name="white">
        <color rgba="1 1 1 1"/>
      </material>
    </collision>
  </link>
  <joint name="head_pan" type="revolute">
    <parent link="head_link"/>
    <child link="head_pan_link"/>
    <origin rpy="0 0 0" xyz="0.10 0.0 0.04"/>
    <axis xyz="0 0 1"/>
    <!--       <limit lower="-${3*pi/4}" upper="${3*pi/4}" velocity="1.0"/> -->
    <limit effort="9.0" lower="-2.39110107523" upper="2.39110107523" velocity="8.30776723947"/>
  </joint>
  <link name="head_pan_link">
    <visual>
      <geometry>
        <box size="0.04 0.04 0.04"/>
      </geometry>
      <origin rpy="0.0 0.0 0.0" xyz="0.0 0.0 0.02"/>
      <material name="white">
        <color rgba="1 1 1 1"/>
      </material>
    </visual>
    <collision>
      <geometry>
        <box size="0.04 0.04 0.04"/>
      </geometry>
      <origin rpy="0.0 0.0 0.0" xyz="0.0 0.0 0.02"/>
      <material name="white">
        <color rgba="1 1 1 1"/>
      </material>
    </collision>
  </link>
  <joint name="head_tilt" type="revolute">
    <parent link="head_pan_link"/>
    <child link="head_tilt_link"/>
    <origin rpy="1.57079632679 0 0" xyz="0.02 0.0 0.02"/>
    <axis xyz="0 0 1"/>
    <!--       <limit lower="-${pi/2}" upper="${(30/180)*pi}" velocity="1.0"/> -->
    <limit effort="9.0" lower="-1.60570291183" upper="0.558505360637" velocity="8.30776723947"/>
  </joint>
  <link name="head_tilt_link">
    <visual>
      <geometry>
        <box size="0.05 0.035 0.18"/>
      </geometry>
      <origin rpy="0 0 0" xyz="0.025 0.0 0.0"/>
      <material name="orange">
        <color rgba="1.0 0.7 0.0 1"/>
      </material>
    </visual>
    <collision>
      <geometry>
        <box size="0.05 0.035 0.18"/>
      </geometry>
      <origin rpy="0 0 0" xyz="0.025 0.0 0.0"/>
      <material name="orange">
        <color rgba="1.0 0.7 0.0 1"/>
      </material>
    </collision>
  </link>
  <joint name="stargazer" type="fixed">
    <parent link="head_link"/>
    <child link="stargazer_link"/>
    <origin rpy="0 0 0" xyz="-0.05 0.0 0.04"/>
  </joint>
  <link name="stargazer_link">
    <visual>
      <geometry>
        <box size="0.07 0.07 0.05"/>
      </geometry>
      <origin rpy="0.0 0.0 0.0" xyz="0.0 0.0 0.025"/>
      <material name="orange">
        <color rgba="1.0 0.7 0.0 1"/>
      </material>
    </visual>
    <collision>
      <geometry>
        <box size="0.07 0.07 0.05"/>
      </geometry>
      <origin rpy="0.0 0.0 0.0" xyz="0.0 0.0 0.025"/>
      <material name="orange">
        <color rgba="1.0 0.7 0.0 1"/>
      </material>
    </collision>
  </link>
  <!-- ************************ Arm model ************************* -->
  <joint name="arm_mount" type="fixed">
    <parent link="torso_lift_link"/>
    <child link="shoulder_link"/>
    <origin rpy="0 0 0" xyz="-0.075 -0.06 0"/>
  </joint>
  <link name="shoulder_link">
    <visual>
      <geometry>
        <box size="0.14 0.12 0.26"/>
      </geometry>
      <origin rpy="0 0 0" xyz="-0.07 0.0 0.0"/>
      <material name="grey_blue">
        <color rgba="0.4 0.4 1.0 1"/>
      </material>
    </visual>
  </link>
  <joint name="shoulder" type="revolute">
    <parent link="shoulder_link"/>
    <child link="upper_arm_link"/>
    <origin rpy="-1.57079632679 -3.14159265359 0.0" xyz="-0.08 0.06 -0.08"/>
    <axis xyz="0 0 1"/>
    <!-- 	    <limit lower="-${3*pi/2}" upper="0.0" velocity="0.013"/> -->
    <limit effort="250.0" lower="-1.22173047639" upper="1.60570291183" velocity="1.27409035395"/>
  </joint>
  <link name="upper_arm_link">
    <visual>
      <geometry>
        <box size="0.41 0.10 0.06"/>
      </geometry>
      <origin rpy="0 0 0" xyz="0.155 0.0 0.03"/>
      <material name="grey_blue">
        <color rgba="0.4 0.4 1.0 1"/>
      </material>
    </visual>
  </link>
  <joint name="elbow" type="revolute">
    <parent link="upper_arm_link"/>
    <child link="lower_arm_link"/>
    <origin rpy="0 0 0" xyz="0.31 0.0 0.06"/>
    <axis xyz="0 0 1"/>
    <!-- 	    <limit lower="0.0" upper="${3*pi/2}" velocity="0.013"/> -->
    <limit effort="200.0" lower="-3.49065850398" upper="1.60570291183" velocity="1.58824961931"/>
  </joint>
  <link name="lower_arm_link">
    <visual>
      <geometry>
        <box size="0.48 0.10 0.06"/>
      </geometry>
      <origin rpy="0 0 0" xyz="0.19 0.00 0.03"/>
      <material name="grey_blue">
        <color rgba="0.4 0.4 1.0 1"/>
      </material>
    </visual>
  </link>
  <joint name="wrist" type="revolute">
    <parent link="lower_arm_link"/>
    <child link="wrist_link"/>
    <origin rpy="0 0 0" xyz="0.40 0.0 0.0"/>
    <axis xyz="0 0 1"/>
    <!-- 	    <limit lower="-${pi}" upper="${pi}" velocity="0.013"/> -->
    <limit effort="51.0" lower="-1.74532925199" upper="1.74532925199" velocity="1.26536370769"/>
  </joint>
  <link name="wrist_link">
    <visual>
      <geometry>
        <cylinder length="0.06" radius="0.03"/>
      </geometry>
      <origin rpy="0 0 0" xyz="0.0 0.0 -0.03"/>
      <material name="grey_blue">
        <color rgba="0.4 0.4 1.0 1"/>
      </material>
    </visual>
  </link>
  <joint name="gripper_fix" type="fixed">
    <parent link="wrist_link"/>
    <child link="gripper_link"/>
    <origin rpy="0.0 0.0 0.0" xyz="0.05 0  -0.06"/>
    <axis xyz="0 0 1"/>
    <limit effort="33.4" lower="-1.6232" upper="1.6232" velocity="0.5"/>
  </joint>
  <link name="gripper_link">
    <visual>
      <geometry>
        <box size="0.04 0.04 0.12"/>
      </geometry>
      <origin rpy="0 0 0" xyz="0.0 0.0 0.0"/>
      <material name="grey_blue">
        <color rgba="0.4 0.4 1.0 1"/>
      </material>
    </visual>
  </link>
  <joint name="gripper" type="prismatic">
    <parent link="gripper_link"/>
    <child link="gripper_left_finger_tip_link"/>
    <origin rpy="0.0 0.0 0.0" xyz="0.02 0.0 -0.05"/>
    <axis xyz="0 1 0"/>
    <!-- 	    <limit lower="0.0" upper="0.04" velocity="0.5"/> -->
    <limit effort="33.4" lower="0.0" upper="0.055" velocity="0.055"/>
    <!-- min -2 ~ 78 deg, 80.8 deg/s -->
  </joint>
  <link name="gripper_left_finger_tip_link">
    <visual>
      <geometry>
        <box size="0.08 0.03 0.02"/>
      </geometry>
      <origin rpy="0 0 0" xyz="0.04 0.0 0.0"/>
      <material name="grey_blue">
        <color rgba="0.4 0.4 1.0 1"/>
      </material>
    </visual>
  </link>
  <joint name="gripper_right_finger_joint" type="fixed">
    <parent link="gripper_link"/>
    <child link="gripper_right_finger_tip_link"/>
    <origin rpy="3.14159265359 0.0 0.0" xyz="0.02 0.0 0.05"/>
    <axis xyz="0 1 0"/>
    <!-- 	    <limit lower="0.0" upper="0.04" velocity="0.5"/> -->
    <limit effort="33.4" lower="0.0" upper="0.055" velocity="0.055"/>
    <!-- min -2 ~ 78 deg, 80.8 deg/s -->
  </joint>
  <link name="gripper_right_finger_tip_link">
    <visual>
      <geometry>
        <box size="0.08 0.03 0.02"/>
      </geometry>
      <origin rpy="0 0 0" xyz="0.04 0.0 0.0"/>
      <material name="grey_blue">
        <color rgba="0.4 0.4 1.0 1"/>
      </material>
    </visual>
  </link>
  <joint name="gripper_center_joint" type="fixed">
    <parent link="gripper_link"/>
    <child link="gripper_center_link"/>
    <origin rpy="0 0 0" xyz="0.10 0 0"/>
  </joint>
  <link name="gripper_center_link">
    <!--       <visual> -->
    <!--         <geometry> -->
    <!--           <box size="0.10 0.15 0.10"/> -->
    <!--         </geometry> -->
    <!--         <origin xyz="0.0 0.0 0.0" rpy="0 0 0"/> -->
    <!--         <xacro:insert_block name="material_orange" /> -->
    <!--       </visual>    -->
  </link>
</robot>
