<?xml version="1.0" ?>
<!-- =================================================================================== -->
<!-- |    This document was autogenerated by xacro from korus_diff_drive.urdf.xacro    | -->
<!-- |    EDITING THIS FILE BY HAND IS NOT RECOMMENDED                                 | -->
<!-- =================================================================================== -->
<robot name="korus" xmlns:xacro="http://www.ros.org/wiki/xacro">
  <!-- ************************ Base model ************************* -->
  <link name="base_footprint"/>
  <joint name="base_joint" type="fixed">
    <parent link="base_footprint"/>
    <child link="base_link"/>
    <origin rpy="0 0 0" xyz="0.0 0.0 0.075"/>
  </joint>
  <link name="base_link">
<!--     <visual> -->
<!--       <geometry> -->
<!--         <mesh filename="package://korus_meta/resources/meshes/base.dae"/> -->
<!--       </geometry> -->
<!--       <origin rpy="0 0 0" xyz="0.0 0.0 0.1045"/> -->
<!--       <material name="white"> -->
<!--         <color rgba="1 1 1 1"/> -->
<!--       </material> -->
<!--     </visual> -->
    <collision>
      <geometry>
        <cylinder length="0.299" radius="0.278"/>
      </geometry>
      <origin rpy="0 0 0" xyz="0.0 0.0 0.1045"/>
    </collision>
  </link>
  <joint name="wheel_left" type="continuous">
    <parent link="base_link"/>
    <child link="wheel_left_link"/>
    <origin rpy="0 0 1.57079632679" xyz="0.0 0.225 0.0"/>
    <limit effort="48.0" velocity="0.5"/>
  </joint>
  <link name="wheel_left_link">
    <visual>
      <geometry>
        <cylinder length="0.03" radius="0.075"/>
      </geometry>
      <origin rpy="0 1.57079632679 0" xyz="0 0 0"/>
      <material name="black">
        <color rgba="0.1 0.1 0.1 1"/>
      </material>
    </visual>
  </link>
  <joint name="wheel_right" type="continuous">
    <parent link="base_link"/>
    <child link="wheel_right_link"/>
    <origin rpy="0 0 1.57079632679" xyz="0.0 -0.225 0.0"/>
    <limit effort="48.0" velocity="0.5"/>
  </joint>
  <link name="wheel_right_link">
    <visual>
      <geometry>
        <cylinder length="0.03" radius="0.075"/>
      </geometry>
      <origin rpy="0 1.57079632679 0" xyz="0 0 0"/>
      <material name="black">
        <color rgba="0.1 0.1 0.1 1"/>
      </material>
    </visual>
  </link>
  <joint name="caster_front_joint" type="fixed">
    <parent link="base_link"/>
    <child link="caster_front_link"/>
    <origin rpy="0 0 1.57079632679" xyz="0.16 0.0 -0.0375"/>
  </joint>
  <link name="caster_front_link">
    <!--       <visual> -->
    <!--         <geometry> -->
    <!--           <cylinder length="${length}" radius="${radius}"/> -->
    <!--         </geometry> -->
    <!--         <origin rpy="0 ${pi/2} 0" xyz="0 0 0"/> -->
    <!--         <material name="black"> -->
    <!--           <color rgba="0.1 0.1 0.1 1"/> -->
    <!--         </material> -->
    <!--       </visual> -->
  </link>
  <joint name="caster_back_left_joint" type="fixed">
    <parent link="base_link"/>
    <child link="caster_back_left_link"/>
    <origin rpy="0 0 1.57079632679" xyz="-0.16 0.147 -0.0375"/>
  </joint>
  <link name="caster_back_left_link">
    <!--       <visual> -->
    <!--         <geometry> -->
    <!--           <cylinder length="${length}" radius="${radius}"/> -->
    <!--         </geometry> -->
    <!--         <origin rpy="0 ${pi/2} 0" xyz="0 0 0"/> -->
    <!--         <material name="black"> -->
    <!--           <color rgba="0.1 0.1 0.1 1"/> -->
    <!--         </material> -->
    <!--       </visual> -->
  </link>
  <joint name="caster_back_right_joint" type="fixed">
    <parent link="base_link"/>
    <child link="caster_back_right_link"/>
    <origin rpy="0 0 1.57079632679" xyz="-0.16 -0.147 -0.0375"/>
  </joint>
  <link name="caster_back_right_link">
    <!--       <visual> -->
    <!--         <geometry> -->
    <!--           <cylinder length="${length}" radius="${radius}"/> -->
    <!--         </geometry> -->
    <!--         <origin rpy="0 ${pi/2} 0" xyz="0 0 0"/> -->
    <!--         <material name="black"> -->
    <!--           <color rgba="0.1 0.1 0.1 1"/> -->
    <!--         </material> -->
    <!--       </visual> -->
  </link>
  <joint name="laser_joint" type="fixed">
    <axis xyz="0 1 0"/>
    <origin rpy="0 0 0" xyz="0.210 0.0 0.21785"/>
    <parent link="base_link"/>
    <child link="laser_link"/>
  </joint>
  <link name="laser_link" type="laser">
    <inertial>
      <mass value="0.001"/>
      <origin rpy="0 0 0" xyz="0 0 0"/>
      <inertia ixx="0.0001" ixy="0" ixz="0" iyy="0.000001" iyz="0" izz="0.0001"/>
    </inertial>
    <!-- visual and collision is commented out, since the laser is inside the base -->
    <!--       <visual> -->
    <!--         <geometry> -->
    <!--            <box size="0.050 0.050 0.0703" /> -->
    <!--    	    </geometry> -->
    <!--         <origin xyz="0.0 0.0 -0.023" rpy="0 0 0"/>  -->
    <!--         <material name="black"> -->
    <!--           <color rgba="0.1 0.1 0.1 1"/> -->
    <!--         </material> -->
    <!--       </visual> -->
    <!--       <collision> -->
    <!--         <geometry> -->
    <!--            <box size="0.050 0.050 0.0703" /> -->
    <!--         </geometry> -->
    <!--         <origin xyz="0.0 0.0 -0.023" rpy="0 0 0"/>  -->
    <!--       </collision> -->
  </link>
  <joint name="sonar_front_left" type="fixed">
    <parent link="base_link"/>
    <child link="sonar_front_left_link"/>
    <origin rpy="0 -0.349065850399 1.0471975512" xyz="0.12411 0.21496 0.09881"/>
  </joint>
  <link name="sonar_front_left_link"/>
  <joint name="sonar_front_middle" type="fixed">
    <parent link="base_link"/>
    <child link="sonar_front_middle_link"/>
    <origin rpy="0 -0.349065850399 0" xyz="0.24822 0.0 0.09881"/>
  </joint>
  <link name="sonar_front_middle_link"/>
  <joint name="sonar_front_right" type="fixed">
    <parent link="base_link"/>
    <child link="sonar_front_right_link"/>
    <origin rpy="0 -0.349065850399 -1.0471975512" xyz="0.12411 -0.21496 0.09881"/>
  </joint>
  <link name="sonar_front_right_link"/>
  <joint name="sonar_back_left" type="fixed">
    <parent link="base_link"/>
    <child link="sonar_back_left_link"/>
    <origin rpy="0 -0.349065850399 2.09439510239" xyz="-0.12411 0.21496 0.09881"/>
  </joint>
  <link name="sonar_back_left_link"/>
  <joint name="sonar_back_middle" type="fixed">
    <parent link="base_link"/>
    <child link="sonar_back_middle_link"/>
    <origin rpy="0 -0.349065850399 -3.14159265359" xyz="-0.24822 0.0 0.09881"/>
  </joint>
  <link name="sonar_back_middle_link"/>
  <joint name="sonar_back_right" type="fixed">
    <parent link="base_link"/>
    <child link="sonar_back_right_link"/>
    <origin rpy="0 -0.349065850399 -2.09439510239" xyz="-0.12411 -0.21496 0.09881"/>
  </joint>
  <link name="sonar_back_right_link"/>
  <joint name="gyro" type="fixed">
    <parent link="base_link"/>
    <child link="gyro_link"/>
    <origin rpy="0 0 0" xyz="0.080 0.165 0.040"/>
  </joint>
  <link name="gyro_link"/>
  <!-- ************************ Body model ************************* -->
  <joint name="torso_turn" type="revolute">
    <parent link="base_link"/>
    <child link="torso_link"/>
    <origin rpy="0 0 0" xyz="0.0 0.0 0.2665"/>
    <axis xyz="0 0 1"/>
    <limit effort="205.0" lower="-3.2463124087" upper="2.79252680318" velocity="1.54810704652"/>
  </joint>
  <link name="torso_link">
<!--     <visual> -->
<!--       <geometry> -->
<!--         <mesh filename="package://korus_meta/resources/meshes/turret.dae"/> -->
<!--       </geometry> -->
<!--       <origin rpy="0 0 0" xyz="0.0 0.0 0.45885"/> -->
<!--       <material name="white"> -->
<!--         <color rgba="1 1 1 1"/> -->
<!--       </material> -->
<!--     </visual> -->
    <collision>
      <!-- torso turn disk -->
      <geometry>
        <cylinder length="0.025" radius="0.278"/>
      </geometry>
      <origin rpy="0 0 0" xyz="0.0 0.0 0.0"/>
    </collision>
    <collision>
      <!-- back -->
      <geometry>
        <box size="0.204 0.25746 0.57888"/>
      </geometry>
      <origin rpy="0 0 0" xyz="-0.13786 0.0 0.30194"/>
    </collision>
    <collision>
      <!-- neck -->
      <geometry>
        <box size="0.030 0.060 0.23262"/>
      </geometry>
      <origin rpy="0 0 0" xyz="-0.12536  0.0 0.70769"/>
    </collision>
    <collision>
      <!-- tablet -->
      <geometry>
        <box size="0.022 0.270 0.1812"/>
      </geometry>
      <origin rpy="0 0 0" xyz="-0.04036 0.0 0.6495"/>
    </collision>
    <collision>
      <!-- head -->
      <geometry>
        <box size="0.227 0.11872 0.0645"/>
      </geometry>
      <origin rpy="0 0 0" xyz="-0.07586 0.0 0.85625"/>
    </collision>
    <collision>
      <!-- stargazer -->
      <geometry>
        <box size="0.09065 0.090 0.0417"/>
      </geometry>
      <origin rpy="0 0 0" xyz="-0.14403 0.0 0.909"/>
    </collision>
  </link>
  <joint name="turret" type="fixed">
    <parent link="torso_link"/>
    <child link="turret_link"/>
    <origin rpy="0 0 0" xyz="-0.13786 0.0 0.0"/>
  </joint>
  <link name="turret_link"/>
  <joint name="torso_lift_offset" type="fixed">
    <parent link="turret_link"/>
    <child link="torso_lift_offset_link"/>
    <origin rpy="0 0 0" xyz="0.10361 0.010 0.170"/>
  </joint>
  <link name="torso_lift_offset_link"/>
  <joint name="torso_lift" type="prismatic">
    <parent link="torso_lift_offset_link"/>
    <child link="torso_lift_link"/>
    <origin rpy="0 0 0" xyz="0 0 0"/>
    <axis xyz="0 0 1"/>
    <limit effort="26.0" lower="-0.002" upper="0.1750" velocity="0.038"/>
  </joint>
  <link name="torso_lift_link"/>
  <joint name="neck" type="fixed">
    <parent link="turret_link"/>
    <child link="neck_link"/>
    <origin rpy="0 0 0" xyz="0.0125 0.0 0.59138"/>
  </joint>
  <link name="neck_link"/>
  <joint name="tablet" type="fixed">
    <parent link="neck_link"/>
    <child link="tablet_link"/>
    <origin rpy="0 0 0" xyz="0.085 0.0 0.05812"/>
  </joint>
  <link name="tablet_link"/>
  <joint name="head" type="fixed">
    <parent link="neck_link"/>
    <child link="head_link"/>
    <origin rpy="0 0 0" xyz="0.0 0.0 0.23262"/>
  </joint>
  <link name="head_link"/>
  <joint name="stargazer" type="fixed">
    <parent link="head_link"/>
    <child link="stargazer_link"/>
    <origin rpy="0 0 3.14159265359" xyz="-0.040 0.0 0.1025"/>
  </joint>
  <link name="stargazer_link"/>
  <joint name="head_pan" type="revolute">
    <parent link="head_link"/>
    <child link="head_pan_link"/>
    <origin rpy="0 0 0" xyz="0.133 0.0 0.0645"/>
    <axis xyz="0 0 1"/>
    <limit effort="9.0" lower="-2.39110107523" upper="2.39110107523" velocity="8.30776723947"/>
  </joint>
  <link name="head_pan_link">
<!--     <visual> -->
<!--       <geometry> -->
<!--         <mesh filename="package://korus_meta/resources/meshes/head_pan.dae"/> -->
<!--       </geometry> -->
<!--       <origin rpy="0.0 0.0 0.0" xyz="-0.0339 0.0 0.02085"/> -->
<!--       <material name="white"> -->
<!--         <color rgba="1 1 1 1"/> -->
<!--       </material> -->
<!--     </visual> -->
    <collision>
      <geometry>
        <box size="0.1122 0.090 0.0417"/>
      </geometry>
      <origin rpy="0.0 0.0 0.0" xyz="-0.0339 0.0 0.02085"/>
    </collision>
  </link>
  <joint name="head_tilt" type="revolute">
    <parent link="head_pan_link"/>
    <child link="head_tilt_link"/>
    <origin rpy="1.57079632679 0 0" xyz="0.01 0.0 0.025"/>
    <!-- x original 0.013 -->
    <axis xyz="0 0 1"/>
    <limit effort="9.0" lower="-1.60570291183" upper="0.558505360637" velocity="8.30776723947"/>
  </joint>
  <link name="head_tilt_link"/>
  <joint name="sensor_3d" type="fixed">
    <parent link="head_tilt_link"/>
    <child link="sensor_3d_link"/>
    <!-- adds to yaw, because the xtion is mounted on its surface which is inclined (approx. 2 deg) -->
    <origin rpy="-1.57079632679 0 0.034" xyz="0.0 0.0 0.0"/>
  </joint>
  <link name="sensor_3d_link">
<!--     <visual> -->
<!--       <geometry> -->
<!--         <mesh filename="package://korus_meta/resources/meshes/xtionpro_w_mount.dae"/> -->
<!--       </geometry> -->
<!--       <origin rpy="0 0 0" xyz="0.0 0.0 0.0225"/> -->
<!--       <material name="black"> -->
<!--         <color rgba="0.1 0.1 0.1 1"/> -->
<!--       </material> -->
<!--     </visual> -->
    <collision>
      <origin rpy="0 0 0" xyz="0.0 0.0032 0.0291"/>
      <geometry>
        <box size="0.036 0.180 0.0298"/>
      </geometry>
    </collision>
  </link>
  <joint name="sensor_3d_fixed" type="fixed">
    <!-- used for head pose control -->
    <parent link="head_link"/>
    <child link="sensor_3d_fixed_link"/>
    <origin rpy="0 0 0" xyz="0.143 0.0 0.1225"/>
  </joint>
  <link name="sensor_3d_fixed_link"/>
  <joint name="sensor_3d_depth_joint" type="fixed">
    <origin rpy="0 0 0" xyz="0.019 0.0435 0.0315"/>
    <parent link="sensor_3d_link"/>
    <child link="sensor_3d_depth_frame"/>
  </joint>
  <link name="sensor_3d_depth_frame"/>
  <joint name="sensor_3d_depth_optical_joint" type="fixed">
    <origin rpy="-1.57079632679 0 -1.57079632679" xyz="0 0 0"/>
    <parent link="sensor_3d_depth_frame"/>
    <child link="sensor_3d_depth_optical_frame"/>
  </joint>
  <link name="sensor_3d_depth_optical_frame"/>
  <joint name="sensor_3d_rgb_joint" type="fixed">
    <!--       <origin xyz="0.0175 0.005 0.0315" rpy="0 -0.017 0" /> already applied in the sensor_3d_link -->
    <origin rpy="0 0 0" xyz="0.0 0.015 0.0315"/>
    <parent link="sensor_3d_link"/>
    <child link="sensor_3d_rgb_frame"/>
  </joint>
  <link name="sensor_3d_rgb_frame"/>
  <joint name="sensor_3d_rgb_optical_joint" type="fixed">
    <origin rpy="-1.57079632679 0 -1.57079632679" xyz="0 0 0"/>
    <parent link="sensor_3d_rgb_frame"/>
    <child link="sensor_3d_rgb_optical_frame"/>
  </joint>
  <link name="sensor_3d_rgb_optical_frame"/>
  <!-- ************************ Arm model ************************* -->
  <joint name="arm_mount" type="fixed">
    <parent link="torso_lift_link"/>
    <child link="shoulder_link"/>
    <origin rpy="1.57079632679 0.0 0.0" xyz="0.08225 0.0 0.0"/>
  </joint>
  <link name="shoulder_link">
<!--     <visual> -->
<!--       <geometry> -->
<!--         <mesh filename="package://korus_meta/resources/meshes/shoulder.dae"/> -->
<!--       </geometry> -->
<!--       <origin rpy="-1.57079632679 0 0" xyz="-0.020 0.070 -0.034"/> -->
<!--       <material name="white"> -->
<!--         <color rgba="1 1 1 1"/> -->
<!--       </material> -->
<!--     </visual> -->
    <collision>
      <geometry>
        <box size="0.122 0.254 0.131"/>
      </geometry>
      <origin rpy="0 0 0" xyz="-0.020 0.070 -0.0655"/>
    </collision>
  </link>
  <joint name="shoulder" type="revolute">
    <parent link="shoulder_link"/>
    <child link="upper_arm_link"/>
    <origin rpy="0 0 0" xyz="0 0 0"/>
    <axis xyz="0 0 1"/>
    <limit effort="250.0" lower="-1.22173047639" upper="1.60570291183" velocity="1.27409035395"/>
  </joint>
  <link name="upper_arm_link">
<!--     <visual> -->
<!--       <geometry> -->
<!--         <mesh filename="package://korus_meta/resources/meshes/upper_arm.dae"/> -->
<!--       </geometry> -->
<!--       <origin rpy="1.57079632679 3.14159265359 1.57079632679" xyz="0.1425 0.001 0.0275"/> -->
<!--       <material name="white"> -->
<!--         <color rgba="1 1 1 1"/> -->
<!--       </material> -->
<!--     </visual> -->
    <collision>
      <geometry>
        <box size="0.378 0.095 0.055"/>
      </geometry>
      <origin rpy="0 0 0" xyz="0.145 0.0 0.028"/>
    </collision>
  </link>
  <joint name="elbow" type="revolute">
    <parent link="upper_arm_link"/>
    <child link="lower_arm_link"/>
    <origin rpy="0 0 0" xyz="0.283 0.0 0.055"/>
    <axis xyz="0 0 1"/>
    <limit effort="200.0" lower="-3.14159265358" upper="1.60570291183" velocity="1.58824961931"/>
  </joint>
  <link name="lower_arm_link">
<!--     <visual> -->
<!--       <geometry> -->
<!--         <mesh filename="package://korus_meta/resources/meshes/lower_arm.dae"/> -->
<!--       </geometry> -->
<!--       <origin rpy="1.57079632679 3.14159265359 1.57079632679" xyz="0.19 0.002 0.027"/> -->
<!--       <material name="white"> -->
<!--         <color rgba="1 1 1 1"/> -->
<!--       </material> -->
<!--     </visual> -->
    <collision>
      <geometry>
        <box size="0.477 0.095 0.057"/>
      </geometry>
      <origin rpy="0 0 0" xyz="0.19426 0.00 0.0285"/>
    </collision>
  </link>
  <joint name="wrist" type="revolute">
    <parent link="lower_arm_link"/>
    <child link="wrist_link"/>
    <origin rpy="0 0 0" xyz="0.382 0.0 0.0"/>
    <axis xyz="0 0 1"/>
    <limit effort="51.0" lower="-1.74532925199" upper="1.74532925199" velocity="1.26536370769"/>
  </joint>
  <link name="wrist_link"/>
  <joint name="palm" type="fixed">
    <parent link="wrist_link"/>
    <child link="palm_link"/>
    <origin rpy="0 0 0" xyz="0.0 0.0 -0.045"/>
  </joint>
  <link name="palm_link">
<!--     <visual> -->
<!--       <geometry> -->
<!--         <mesh filename="package://korus_meta/resources/meshes/palm.dae"/> -->
<!--       </geometry> -->
<!--       <origin rpy="-1.57079632679 0 0" xyz="0.0395 0.001 0.0025"/> -->
<!--       <material name="white"> -->
<!--         <color rgba="1 1 1 1"/> -->
<!--       </material> -->
<!--     </visual> -->
    <collision>
      <geometry>
        <cylinder length="0.0854" radius="0.038"/>
      </geometry>
      <origin rpy="0 0 0" xyz="0.0 0.0 0.0035"/>
    </collision>
    <collision>
      <geometry>
        <box size="0.1044 0.077 0.0804"/>
      </geometry>
      <origin rpy="0 0 0" xyz="0.0522 0.0 0.0"/>
    </collision>
  </link>
  <joint name="gripper_center" type="fixed">
    <parent link="palm_link"/>
    <child link="gripper_center_link"/>
    <origin rpy="0 0 0" xyz="0.15 0.0 0.0"/>
  </joint>
  <link name="gripper_center_link"/>
  <joint name="gripper" type="revolute">
    <parent link="palm_link"/>
    <child link="gripper_link"/>
    <origin rpy="-1.57079632679 0 0" xyz="0.08 0.0 0.0"/>
    <axis xyz="0 0 1"/>
    <limit effort="33.4" lower="-0.0349065850398" upper="1.36135681655" velocity="1.41022603561"/>
  </joint>
  <link name="gripper_link"/>
  <joint name="finger_left_knuckle_1" type="revolute">
    <parent link="palm_link"/>
    <child link="finger_left_knuckle_1_link"/>
    <origin rpy="1.57079632679 -0.174532925199 0" xyz="0.0925 0.0 -0.022"/>
    <axis xyz="0 0 1"/>
    <limit effort="33.4" lower="-1.36135681655" upper="0.0349065850398" velocity="1.41022603561"/>
  </joint>
  <link name="finger_left_knuckle_1_link">
<!--     <visual> -->
<!--       <geometry> -->
<!--         <mesh filename="package://korus_meta/resources/meshes/finger01.dae"/> -->
<!--       </geometry> -->
<!--       <origin rpy="0 0 0" xyz="0.02975 0.0 0.0"/> -->
<!--       <material name="white"> -->
<!--         <color rgba="1 1 1 1"/> -->
<!--       </material> -->
<!--     </visual> -->
    <collision>
      <geometry>
        <box size="0.0595 0.0247 0.0306"/>
      </geometry>
      <origin rpy="0 0 0" xyz="0.02975 0.0 0.0"/>
    </collision>
  </link>
  <joint name="finger_left_knuckle_2" type="revolute">
    <parent link="finger_left_knuckle_1_link"/>
    <child link="finger_left_knuckle_2_link"/>
    <origin rpy="0 0 -0.174532925199" xyz="0.051 0.0 0.0"/>
    <axis xyz="0 0 1"/>
    <limit effort="33.4" lower="-0.0349065850398" upper="1.36135681655" velocity="1.41022603561"/>
  </joint>
  <link name="finger_left_knuckle_2_link">
<!--     <visual> -->
<!--       <geometry> -->
<!--         <mesh filename="package://korus_meta/resources/meshes/finger02.dae"/> -->
<!--       </geometry> -->
<!--       <origin rpy="0 0 0" xyz="0.0325 0.0 0.0"/> -->
<!--       <material name="white"> -->
<!--         <color rgba="1 1 1 1"/> -->
<!--       </material> -->
<!--     </visual> -->
    <collision>
      <geometry>
        <box size="0.065 0.0247 0.0306"/>
      </geometry>
      <origin rpy="0 0 0" xyz="0.0325 0.0 0.0"/>
    </collision>
  </link>
  <joint name="finger_left_tip" type="fixed">
    <parent link="finger_left_knuckle_2_link"/>
    <child link="finger_left_tip_link"/>
    <origin rpy="0 0 0" xyz="0.065 0.0 0.0"/>
  </joint>
  <link name="finger_left_tip_link"/>
  <joint name="finger_right_knuckle_1" type="revolute">
    <parent link="palm_link"/>
    <child link="finger_right_knuckle_1_link"/>
    <origin rpy="-1.57079632679 0.174532925199 0.0" xyz="0.0925 0.0 0.022"/>
    <axis xyz="0 0 1"/>
    <limit effort="33.4" lower="-1.36135681655" upper="0.0349065850398" velocity="1.41022603561"/>
  </joint>
  <link name="finger_right_knuckle_1_link">
<!--     <visual> -->
<!--       <geometry> -->
<!--         <mesh filename="package://korus_meta/resources/meshes/finger01.dae"/> -->
<!--       </geometry> -->
<!--       <origin rpy="0 0 0" xyz="0.02975 0.0 0.0"/> -->
<!--       <material name="white"> -->
<!--         <color rgba="1 1 1 1"/> -->
<!--       </material> -->
<!--     </visual> -->
    <collision>
      <geometry>
        <box size="0.0595 0.0247 0.0306"/>
      </geometry>
      <origin rpy="0 0 0" xyz="0.02975 0.0 0.0"/>
    </collision>
  </link>
  <joint name="finger_right_knuckle_2" type="revolute">
    <parent link="finger_right_knuckle_1_link"/>
    <child link="finger_right_knuckle_2_link"/>
    <origin rpy="0 0 -0.174532925199" xyz="0.051 0.0 0.0"/>
    <axis xyz="0 0 1"/>
    <limit effort="33.4" lower="-0.0349065850398" upper="1.36135681655" velocity="1.41022603561"/>
  </joint>
  <link name="finger_right_knuckle_2_link">
<!--     <visual> -->
<!--       <geometry> -->
        <!--           <mesh filename="package://korus_meta/resources/meshes/finger02.dae" /> -->
<!--         <box size="0.065 0.0247 0.08"/> -->
<!--       </geometry> -->
<!--       <origin rpy="0 0 0" xyz="0.0325 0.0 0.0"/> -->
<!--       <material name="white"> -->
<!--         <color rgba="1 1 1 1"/> -->
<!--       </material> -->
<!--     </visual> -->
    <collision>
      <geometry>
        <box size="0.065 0.0247 0.08"/>
      </geometry>
      <origin rpy="0 0 0" xyz="0.0325 0.0 0.0"/>
    </collision>
  </link>
  <joint name="finger_right_tip" type="fixed">
    <parent link="finger_right_knuckle_2_link"/>
    <child link="finger_right_tip_link"/>
    <origin rpy="0 0 0" xyz="0.065 0.0 0.0"/>
  </joint>
  <link name="finger_right_tip_link"/>
  <joint name="gripper_camera" type="fixed">
    <parent link="palm_link"/>
    <child link="gripper_camera_link"/>
    <origin rpy="0.0 1.57079632679 0.0" xyz="0.10015 0 0"/>
  </joint>
  <link name="gripper_camera_link">
    <visual>
      <geometry>
        <cylinder length="0.01" radius="0.01"/>
      </geometry>
      <origin rpy="0 0 0" xyz="0.0 0.0 0.0"/>
      <material name="black">
        <color rgba="0.1 0.1 0.1 1"/>
      </material>
    </visual>
    <collision>
      <geometry>
        <cylinder length="0.01" radius="0.01"/>
      </geometry>
      <origin rpy="0 0 0" xyz="0.0 0.0 0.0"/>
    </collision>
  </link>
</robot>
